<?xml version="1.0"?>
<robot name="panai_robot" xmlns:xacro="http://www.ros.org/wiki/xacro">
  <material name="blue">
    <color rgba="0.2 0.2 0.8 1"/>
  </material>

  <link name="base_link">
    <visual>
      <geometry>
        <box size="0.4 0.3 0.1"/>
      </geometry>
      <material name="blue"/>
    </visual>
    <collision>
      <geometry>
        <box size="0.4 0.3 0.1"/>
      </geometry>
    </collision>
    <inertial>
      <mass value="5.0"/>
      <inertia ixx="0.05" ixy="0" ixz="0" iyy="0.08" iyz="0" izz="0.1"/>
    </inertial>
  </link>

  <xacro:macro name="wheel" params="name x y">
    <link name="${name}_link">
      <visual>
        <geometry>
          <cylinder radius="0.05" length="0.04"/>
        </geometry>
      </visual>
      <collision>
        <geometry>
          <cylinder radius="0.05" length="0.04"/>
        </geometry>
      </collision>
      <inertial>
        <mass value="0.5"/>
        <inertia ixx="0.001" ixy="0" ixz="0" iyy="0.001" iyz="0" izz="0.001"/>
      </inertial>
    </link>
    <joint name="${name}_joint" type="continuous">
      <parent link="base_link"/>
      <child link="${name}_link"/>
      <origin xyz="${x} ${y} -0.05" rpy="1.570796 0 0"/>
      <axis xyz="0 0 1"/>
    </joint>
  </xacro:macro>

  <xacro:wheel name="front_left_wheel" x="0.15" y="0.17"/>
  <xacro:wheel name="rear_left_wheel" x="-0.15" y="0.17"/>
  <xacro:wheel name="front_right_wheel" x="0.15" y="-0.17"/>
  <xacro:wheel name="rear_right_wheel" x="-0.15" y="-0.17"/>

  <!-- Точки крепления датчиков -->
  <link name="camera_link"/>
  <joint name="camera_joint" type="fixed">
    <parent link="base_link"/>
    <child link="camera_link"/>
    <origin xyz="0.2 0 0.1"/>
  </joint>

  <link name="laser_link"/>
  <joint name="laser_joint" type="fixed">
    <parent link="base_link"/>
    <child link="laser_link"/>
    <origin xyz="0.2 0 0.05"/>
  </joint>

  <link name="acoustic_link"/>
  <joint name="acoustic_joint" type="fixed">
    <parent link="base_link"/>
    <child link="acoustic_link"/>
    <origin xyz="-0.1 0.15 -0.05"/>
  </joint>

  <gazebo>
    <plugin filename="gz-sim-diff-drive-system" name="gz::sim::systems::DiffDrive">
      <left_joint>front_left_wheel_joint</left_joint>
      <left_joint>rear_left_wheel_joint</left_joint>
      <right_joint>front_right_wheel_joint</right_joint>
      <right_joint>rear_right_wheel_joint</right_joint>
      <wheel_separation>0.34</wheel_separation>
      <wheel_radius>0.05</wheel_radius>
      <odom_publish_frequency>50</odom_publish_frequency>
      <topic>/cmd_vel</topic>
      <odom_topic>/odom</odom_topic>
      <tf_topic>/tf</tf_topic>
      <frame_id>odom</frame_id>
      <child_frame_id>base_link</child_frame_id>
    </plugin>
  </gazebo>
</robot>
